============================= test session starts ==============================
platform linux -- Python 3.10.16, pytest-8.3.5, pluggy-1.6.0
rootdir: /home/jn_cndt4/project/code repair/BugAgent/BugAgent_1.3/data/QuixBugs_test
plugins: anyio-4.9.0, timeout-2.4.0
timeout: 5.0s
timeout method: signal
timeout func_only: False
collected 5 items

python_testcases/test_depth_first_search.py ....F                        [100%]

=================================== FAILURES ===================================
____________________________________ test5 _____________________________________

    def test5():
        """Case 5: Graph with cycles
        Output: Path found!
        """
    
        nodef = Node("F")
        nodee = Node("E")
        noded = Node("D")
        nodec = Node("C", None, [nodef])
        nodeb = Node("B", None, [nodee])
        nodea = Node("A", None, [nodeb, nodec, noded])
    
        nodee.successors = [nodea]
    
>       path_found = depth_first_search(nodea, nodef)

python_testcases/test_depth_first_search.py:83: 
_ _ _ _ _ _ _ _ _ _ _ _ _ _ _ _ _ _ _ _ _ _ _ _ _ _ _ _ _ _ _ _ _ _ _ _ _ _ _ _ 
python_programs/depth_first_search.py:14: in depth_first_search
    return search_from(startnode)
python_programs/depth_first_search.py:10: in search_from
    return any(
python_programs/depth_first_search.py:11: in <genexpr>
    search_from(nextnode) for nextnode in node.successors
python_programs/depth_first_search.py:10: in search_from
    return any(
python_programs/depth_first_search.py:11: in <genexpr>
    search_from(nextnode) for nextnode in node.successors
python_programs/depth_first_search.py:10: in search_from
    return any(
python_programs/depth_first_search.py:11: in <genexpr>
    search_from(nextnode) for nextnode in node.successors
python_programs/depth_first_search.py:10: in search_from
    return any(
E   RecursionError: maximum recursion depth exceeded
!!! Recursion detected (same locals & position)
=========================== short test summary info ============================
FAILED python_testcases/test_depth_first_search.py::test5 - RecursionError: m...
========================= 1 failed, 4 passed in 0.03s ==========================
