============================= test session starts ==============================
platform linux -- Python 3.10.16, pytest-8.3.5, pluggy-1.6.0
rootdir: /home/jn_cndt4/project/code repair/BugAgent/BugAgent_1.3/data/QuixBugs_test
plugins: anyio-4.9.0, timeout-2.4.0
timeout: 5.0s
timeout method: signal
timeout func_only: False
collected 7 items

python_testcases/test_find_first_in_sorted.py .FF.F..                    [100%]

=================================== FAILURES ===================================
__________________ test_find_first_in_sorted[input_data1--1] ___________________

input_data = [[3, 4, 5, 5, 5, 5, ...], 7], expected = -1

    @pytest.mark.parametrize("input_data,expected", testdata)
    def test_find_first_in_sorted(input_data, expected):
>       assert find_first_in_sorted(*input_data) == expected

python_testcases/test_find_first_in_sorted.py:15: 
_ _ _ _ _ _ _ _ _ _ _ _ _ _ _ _ _ _ _ _ _ _ _ _ _ _ _ _ _ _ _ _ _ _ _ _ _ _ _ _ 

arr = [3, 4, 5, 5, 5, 5, ...], x = 7

    def find_first_in_sorted(arr, x):
        lo = 0
        hi = len(arr)
    
        while lo <= hi:
            mid = (lo + hi) // 2
    
>           if x == arr[mid] and (mid == 0 or x != arr[mid - 1]):
E           IndexError: list index out of range

python_programs/find_first_in_sorted.py:8: IndexError
__________________ test_find_first_in_sorted[input_data2--1] ___________________

input_data = [[3, 4, 5, 5, 5, 5, ...], 2], expected = -1

    @pytest.mark.parametrize("input_data,expected", testdata)
    def test_find_first_in_sorted(input_data, expected):
>       assert find_first_in_sorted(*input_data) == expected

python_testcases/test_find_first_in_sorted.py:15: 
_ _ _ _ _ _ _ _ _ _ _ _ _ _ _ _ _ _ _ _ _ _ _ _ _ _ _ _ _ _ _ _ _ _ _ _ _ _ _ _ 

arr = [3, 4, 5, 5, 5, 5, ...], x = 2

    def find_first_in_sorted(arr, x):
        lo = 0
        hi = len(arr)
    
        while lo <= hi:
            mid = (lo + hi) // 2
    
>           if x == arr[mid] and (mid == 0 or x != arr[mid - 1]):
E           Failed: Timeout (>5.0s) from pytest-timeout.

python_programs/find_first_in_sorted.py:8: Failed
__________________ test_find_first_in_sorted[input_data4--1] ___________________

input_data = [[0, 1, 6, 8, 13, 14, ...], 80], expected = -1

    @pytest.mark.parametrize("input_data,expected", testdata)
    def test_find_first_in_sorted(input_data, expected):
>       assert find_first_in_sorted(*input_data) == expected

python_testcases/test_find_first_in_sorted.py:15: 
_ _ _ _ _ _ _ _ _ _ _ _ _ _ _ _ _ _ _ _ _ _ _ _ _ _ _ _ _ _ _ _ _ _ _ _ _ _ _ _ 

arr = [0, 1, 6, 8, 13, 14, ...], x = 80

    def find_first_in_sorted(arr, x):
        lo = 0
        hi = len(arr)
    
>       while lo <= hi:
E       Failed: Timeout (>5.0s) from pytest-timeout.

python_programs/find_first_in_sorted.py:5: Failed
=========================== short test summary info ============================
FAILED python_testcases/test_find_first_in_sorted.py::test_find_first_in_sorted[input_data1--1]
FAILED python_testcases/test_find_first_in_sorted.py::test_find_first_in_sorted[input_data2--1]
FAILED python_testcases/test_find_first_in_sorted.py::test_find_first_in_sorted[input_data4--1]
========================= 3 failed, 4 passed in 10.03s =========================
