============================= test session starts ==============================
platform linux -- Python 3.10.16, pytest-8.3.5, pluggy-1.6.0
rootdir: /home/jn_cndt4/project/code repair/BugAgent/BugAgent_1.3/data/QuixBugs_test
plugins: anyio-4.9.0, timeout-2.4.0
timeout: 5.0s
timeout method: signal
timeout func_only: False
collected 4 items

python_testcases/test_kheapsort.py .FFF                                  [100%]

=================================== FAILURES ===================================
____________________ test_kheapsort[input_data1-expected1] _____________________

input_data = [[3, 2, 1, 5, 4], 2], expected = [1, 2, 3, 4, 5]

    @pytest.mark.parametrize("input_data,expected", testdata)
    def test_kheapsort(input_data, expected):
>       assert list(kheapsort(*input_data)) == expected
E       assert [2, 2, 1, 3, 3, 4, ...] == [1, 2, 3, 4, 5]
E         
E         At index 0 diff: 2 != 1
E         Left contains 2 more items, first extra item: 4
E         Use -v to get more diff

python_testcases/test_kheapsort.py:15: AssertionError
____________________ test_kheapsort[input_data2-expected2] _____________________

input_data = [[5, 4, 3, 2, 1], 4], expected = [1, 2, 3, 4, 5]

    @pytest.mark.parametrize("input_data,expected", testdata)
    def test_kheapsort(input_data, expected):
>       assert list(kheapsort(*input_data)) == expected
E       assert [2, 3, 3, 2, 1, 4, ...] == [1, 2, 3, 4, 5]
E         
E         At index 0 diff: 2 != 1
E         Left contains 4 more items, first extra item: 4
E         Use -v to get more diff

python_testcases/test_kheapsort.py:15: AssertionError
____________________ test_kheapsort[input_data3-expected3] _____________________

input_data = [[3, 12, 5, 1, 6], 3], expected = [1, 3, 5, 6, 12]

    @pytest.mark.parametrize("input_data,expected", testdata)
    def test_kheapsort(input_data, expected):
>       assert list(kheapsort(*input_data)) == expected
E       assert [3, 3, 5, 1, 5, 6, ...] == [1, 3, 5, 6, 12]
E         
E         At index 0 diff: 3 != 1
E         Left contains 3 more items, first extra item: 6
E         Use -v to get more diff

python_testcases/test_kheapsort.py:15: AssertionError
=========================== short test summary info ============================
FAILED python_testcases/test_kheapsort.py::test_kheapsort[input_data1-expected1]
FAILED python_testcases/test_kheapsort.py::test_kheapsort[input_data2-expected2]
FAILED python_testcases/test_kheapsort.py::test_kheapsort[input_data3-expected3]
========================= 3 failed, 1 passed in 0.03s ==========================
