============================= test session starts ==============================
platform linux -- Python 3.10.16, pytest-8.3.5, pluggy-1.6.0
rootdir: /home/jn_cndt4/project/code repair/BugAgent/BugAgent_1.3/data/QuixBugs_test
plugins: anyio-4.9.0, timeout-2.4.0
timeout: 5.0s
timeout method: signal
timeout func_only: False
collected 6 items

python_testcases/test_max_sublist_sum.py FF.F.F                          [100%]

=================================== FAILURES ===================================
_____________________ test_max_sublist_sum[input_data0-5] ______________________

input_data = [[4, -5, 2, 1, -1, 3]], expected = 5

    @pytest.mark.parametrize("input_data,expected", testdata)
    def test_max_sublist_sum(input_data, expected):
>       assert max_sublist_sum(*input_data) == expected
E       assert 4 == 5
E        +  where 4 = max_sublist_sum(*[[4, -5, 2, 1, -1, 3]])

python_testcases/test_max_sublist_sum.py:15: AssertionError
_____________________ test_max_sublist_sum[input_data1-4] ______________________

input_data = [[0, -1, 2, -1, 3, -1, ...]], expected = 4

    @pytest.mark.parametrize("input_data,expected", testdata)
    def test_max_sublist_sum(input_data, expected):
>       assert max_sublist_sum(*input_data) == expected
E       assert 3 == 4
E        +  where 3 = max_sublist_sum(*[[0, -1, 2, -1, 3, -1, ...]])

python_testcases/test_max_sublist_sum.py:15: AssertionError
_____________________ test_max_sublist_sum[input_data3-19] _____________________

input_data = [[4, -2, -8, 5, -2, 7, ...]], expected = 19

    @pytest.mark.parametrize("input_data,expected", testdata)
    def test_max_sublist_sum(input_data, expected):
>       assert max_sublist_sum(*input_data) == expected
E       assert 13 == 19
E        +  where 13 = max_sublist_sum(*[[4, -2, -8, 5, -2, 7, ...]])

python_testcases/test_max_sublist_sum.py:15: AssertionError
_____________________ test_max_sublist_sum[input_data5-6] ______________________

input_data = [[-2, 1, -3, 4, -1, 2, ...]], expected = 6

    @pytest.mark.parametrize("input_data,expected", testdata)
    def test_max_sublist_sum(input_data, expected):
>       assert max_sublist_sum(*input_data) == expected
E       assert 2 == 6
E        +  where 2 = max_sublist_sum(*[[-2, 1, -3, 4, -1, 2, ...]])

python_testcases/test_max_sublist_sum.py:15: AssertionError
=========================== short test summary info ============================
FAILED python_testcases/test_max_sublist_sum.py::test_max_sublist_sum[input_data0-5]
FAILED python_testcases/test_max_sublist_sum.py::test_max_sublist_sum[input_data1-4]
FAILED python_testcases/test_max_sublist_sum.py::test_max_sublist_sum[input_data3-19]
FAILED python_testcases/test_max_sublist_sum.py::test_max_sublist_sum[input_data5-6]
========================= 4 failed, 2 passed in 0.03s ==========================
