============================= test session starts ==============================
platform linux -- Python 3.10.16, pytest-8.3.5, pluggy-1.6.0
rootdir: /home/jn_cndt4/project/code repair/BugAgent/BugAgent_1.3/data/QuixBugs_test
plugins: anyio-4.9.0, timeout-2.4.0
timeout: 5.0s
timeout method: signal
timeout func_only: False
collected 5 items

python_testcases/test_next_palindrome.py ....F                           [100%]

=================================== FAILURES ===================================
_________________ test_next_palindrome[input_data4-expected4] __________________

input_data = [[0, 0, 0]], expected = [1, 0, 0, 1]

    @pytest.mark.parametrize("input_data,expected", testdata)
    def test_next_palindrome(input_data, expected):
>       assert next_palindrome(*input_data) == expected
E       assert [1, 0, 0, 0, 1] == [1, 0, 0, 1]
E         
E         At index 3 diff: 0 != 1
E         Left contains one more item: 1
E         Use -v to get more diff

python_testcases/test_next_palindrome.py:15: AssertionError
=========================== short test summary info ============================
FAILED python_testcases/test_next_palindrome.py::test_next_palindrome[input_data4-expected4]
========================= 1 failed, 4 passed in 0.03s ==========================
