============================= test session starts ==============================
platform linux -- Python 3.10.16, pytest-8.3.5, pluggy-1.6.0
rootdir: /home/jn_cndt4/project/code repair/BugAgent/BugAgent_1.3/data/QuixBugs_test
plugins: anyio-4.9.0, timeout-2.4.0
timeout: 5.0s
timeout method: signal
timeout func_only: False
collected 13 items

python_testcases/test_quicksort.py .F...........                         [100%]

=================================== FAILURES ===================================
____________________ test_quicksort[input_data1-expected1] _____________________

input_data = [[3, 1, 4, 1, 5, 9, ...]], expected = [1, 1, 2, 3, 3, 3, ...]

    @pytest.mark.parametrize("input_data,expected", testdata)
    def test_quicksort(input_data, expected):
>       assert quicksort(*input_data) == expected
E       assert [1, 2, 3, 4, 5, 6, ...] == [1, 1, 2, 3, 3, 3, ...]
E         
E         At index 1 diff: 2 != 1
E         Right contains 7 more items, first extra item: 5
E         Use -v to get more diff

python_testcases/test_quicksort.py:15: AssertionError
=========================== short test summary info ============================
FAILED python_testcases/test_quicksort.py::test_quicksort[input_data1-expected1]
========================= 1 failed, 12 passed in 0.03s =========================
